"use server";

import * as z from "zod";
import { LoginSchema } from "@/schemas";
import { signIn } from "@/auth";
import { DEFAULT_LOGIN_REDIRECT } from "@/routes";
import { AuthError } from "next-auth";
import { getUserByEmail } from "@/data/user";
import { generateVerificationToken } from "@/lib/token";
import { sendVerificationEmail } from "@/lib/mail";

export const login = async (values: z.infer<typeof LoginSchema>) => {
  const validatedFields = LoginSchema.safeParse(values);

  if (!validatedFields.success) {
    return { error: "Invalid Field!" };
  }

  const { email, password } = validatedFields.data;
  const existingUser = await getUserByEmail(email);
  if (!existingUser || !existingUser.email || !existingUser.password) {
    return { error: "Email Doesn't Exists!" };
  }
  // TODO: Sending an confirmation Email
  if (!existingUser.emailVerified) {
    const verificationToken = await generateVerificationToken(
      existingUser.email
    );

    await sendVerificationEmail(
      verificationToken.email,
      verificationToken.token
    );

    return { success: "Confirmation Email Sent!" };
  }

  // TODO: Need to protect Signin API using callback

  try {
    await signIn("credentials", {
      email,
      password,
      redirectTo: DEFAULT_LOGIN_REDIRECT,
    });
  } catch (error) {
    if (error instanceof AuthError) {
      switch (error.type) {
        case "CredentialsSignin":
          return { error: `Invalid Credentials` };
        default:
          return { error: "Something Went Wrong!" };
      }
    }

    // it is a nextjs bug. You need to throw error explicitly
    throw error;
  }
};
